ERROR:django.request:Internal Server Error: /api/v1/predict/
Traceback (most recent call last):
  File "/Users/anandaryanizar/anaconda3/envs/tf/lib/python3.6/site-packages/django/db/backends/utils.py", line 84, in _execute
    return self.cursor.execute(sql, params)
  File "/Users/anandaryanizar/anaconda3/envs/tf/lib/python3.6/site-packages/django/db/backends/sqlite3/base.py", line 383, in execute
    return Database.Cursor.execute(self, query, params)
sqlite3.OperationalError: no such column: classifier_classifier.model

The above exception was the direct cause of the following exception:

Traceback (most recent call last):
  File "/Users/anandaryanizar/anaconda3/envs/tf/lib/python3.6/site-packages/django/core/handlers/exception.py", line 34, in inner
    response = get_response(request)
  File "/Users/anandaryanizar/anaconda3/envs/tf/lib/python3.6/site-packages/django/core/handlers/base.py", line 115, in _get_response
    response = self.process_exception_by_middleware(e, request)
  File "/Users/anandaryanizar/anaconda3/envs/tf/lib/python3.6/site-packages/django/core/handlers/base.py", line 113, in _get_response
    response = wrapped_callback(request, *callback_args, **callback_kwargs)
  File "/Users/anandaryanizar/anaconda3/envs/tf/lib/python3.6/site-packages/django/views/decorators/csrf.py", line 54, in wrapped_view
    return view_func(*args, **kwargs)
  File "/Users/anandaryanizar/anaconda3/envs/tf/lib/python3.6/site-packages/django/views/generic/base.py", line 71, in view
    return self.dispatch(request, *args, **kwargs)
  File "/Users/anandaryanizar/anaconda3/envs/tf/lib/python3.6/site-packages/rest_framework/views.py", line 495, in dispatch
    response = self.handle_exception(exc)
  File "/Users/anandaryanizar/anaconda3/envs/tf/lib/python3.6/site-packages/rest_framework/views.py", line 455, in handle_exception
    self.raise_uncaught_exception(exc)
  File "/Users/anandaryanizar/anaconda3/envs/tf/lib/python3.6/site-packages/rest_framework/views.py", line 492, in dispatch
    response = handler(request, *args, **kwargs)
  File "/Users/anandaryanizar/Documents/Projects/Deep Learning/FakeNewsClassifier/classifier/classifier_api.py", line 42, in get
    return Response(serializer.data, status=status.HTTP_200_OK)
  File "/Users/anandaryanizar/anaconda3/envs/tf/lib/python3.6/site-packages/rest_framework/serializers.py", line 768, in data
    ret = super(ListSerializer, self).data
  File "/Users/anandaryanizar/anaconda3/envs/tf/lib/python3.6/site-packages/rest_framework/serializers.py", line 262, in data
    self._data = self.to_representation(self.instance)
  File "/Users/anandaryanizar/anaconda3/envs/tf/lib/python3.6/site-packages/rest_framework/serializers.py", line 686, in to_representation
    self.child.to_representation(item) for item in iterable
  File "/Users/anandaryanizar/anaconda3/envs/tf/lib/python3.6/site-packages/django/db/models/query.py", line 274, in __iter__
    self._fetch_all()
  File "/Users/anandaryanizar/anaconda3/envs/tf/lib/python3.6/site-packages/django/db/models/query.py", line 1242, in _fetch_all
    self._result_cache = list(self._iterable_class(self))
  File "/Users/anandaryanizar/anaconda3/envs/tf/lib/python3.6/site-packages/django/db/models/query.py", line 55, in __iter__
    results = compiler.execute_sql(chunked_fetch=self.chunked_fetch, chunk_size=self.chunk_size)
  File "/Users/anandaryanizar/anaconda3/envs/tf/lib/python3.6/site-packages/django/db/models/sql/compiler.py", line 1100, in execute_sql
    cursor.execute(sql, params)
  File "/Users/anandaryanizar/anaconda3/envs/tf/lib/python3.6/site-packages/django/db/backends/utils.py", line 99, in execute
    return super().execute(sql, params)
  File "/Users/anandaryanizar/anaconda3/envs/tf/lib/python3.6/site-packages/django/db/backends/utils.py", line 67, in execute
    return self._execute_with_wrappers(sql, params, many=False, executor=self._execute)
  File "/Users/anandaryanizar/anaconda3/envs/tf/lib/python3.6/site-packages/django/db/backends/utils.py", line 76, in _execute_with_wrappers
    return executor(sql, params, many, context)
  File "/Users/anandaryanizar/anaconda3/envs/tf/lib/python3.6/site-packages/django/db/backends/utils.py", line 84, in _execute
    return self.cursor.execute(sql, params)
  File "/Users/anandaryanizar/anaconda3/envs/tf/lib/python3.6/site-packages/django/db/utils.py", line 89, in __exit__
    raise dj_exc_value.with_traceback(traceback) from exc_value
  File "/Users/anandaryanizar/anaconda3/envs/tf/lib/python3.6/site-packages/django/db/backends/utils.py", line 84, in _execute
    return self.cursor.execute(sql, params)
  File "/Users/anandaryanizar/anaconda3/envs/tf/lib/python3.6/site-packages/django/db/backends/sqlite3/base.py", line 383, in execute
    return Database.Cursor.execute(self, query, params)
django.db.utils.OperationalError: no such column: classifier_classifier.model
ERROR:django.request:Internal Server Error: /api/v1/predict/
Traceback (most recent call last):
  File "/Users/anandaryanizar/anaconda3/envs/tf/lib/python3.6/site-packages/django/db/backends/utils.py", line 84, in _execute
    return self.cursor.execute(sql, params)
  File "/Users/anandaryanizar/anaconda3/envs/tf/lib/python3.6/site-packages/django/db/backends/sqlite3/base.py", line 383, in execute
    return Database.Cursor.execute(self, query, params)
sqlite3.OperationalError: no such column: classifier_classifier.model

The above exception was the direct cause of the following exception:

Traceback (most recent call last):
  File "/Users/anandaryanizar/anaconda3/envs/tf/lib/python3.6/site-packages/django/core/handlers/exception.py", line 34, in inner
    response = get_response(request)
  File "/Users/anandaryanizar/anaconda3/envs/tf/lib/python3.6/site-packages/django/core/handlers/base.py", line 115, in _get_response
    response = self.process_exception_by_middleware(e, request)
  File "/Users/anandaryanizar/anaconda3/envs/tf/lib/python3.6/site-packages/django/core/handlers/base.py", line 113, in _get_response
    response = wrapped_callback(request, *callback_args, **callback_kwargs)
  File "/Users/anandaryanizar/anaconda3/envs/tf/lib/python3.6/site-packages/django/views/decorators/csrf.py", line 54, in wrapped_view
    return view_func(*args, **kwargs)
  File "/Users/anandaryanizar/anaconda3/envs/tf/lib/python3.6/site-packages/django/views/generic/base.py", line 71, in view
    return self.dispatch(request, *args, **kwargs)
  File "/Users/anandaryanizar/anaconda3/envs/tf/lib/python3.6/site-packages/rest_framework/views.py", line 495, in dispatch
    response = self.handle_exception(exc)
  File "/Users/anandaryanizar/anaconda3/envs/tf/lib/python3.6/site-packages/rest_framework/views.py", line 455, in handle_exception
    self.raise_uncaught_exception(exc)
  File "/Users/anandaryanizar/anaconda3/envs/tf/lib/python3.6/site-packages/rest_framework/views.py", line 492, in dispatch
    response = handler(request, *args, **kwargs)
  File "/Users/anandaryanizar/Documents/Projects/Deep Learning/FakeNewsClassifier/classifier/classifier_api.py", line 42, in get
    return Response(serializer.data, status=status.HTTP_200_OK)
  File "/Users/anandaryanizar/anaconda3/envs/tf/lib/python3.6/site-packages/rest_framework/serializers.py", line 768, in data
    ret = super(ListSerializer, self).data
  File "/Users/anandaryanizar/anaconda3/envs/tf/lib/python3.6/site-packages/rest_framework/serializers.py", line 262, in data
    self._data = self.to_representation(self.instance)
  File "/Users/anandaryanizar/anaconda3/envs/tf/lib/python3.6/site-packages/rest_framework/serializers.py", line 686, in to_representation
    self.child.to_representation(item) for item in iterable
  File "/Users/anandaryanizar/anaconda3/envs/tf/lib/python3.6/site-packages/django/db/models/query.py", line 274, in __iter__
    self._fetch_all()
  File "/Users/anandaryanizar/anaconda3/envs/tf/lib/python3.6/site-packages/django/db/models/query.py", line 1242, in _fetch_all
    self._result_cache = list(self._iterable_class(self))
  File "/Users/anandaryanizar/anaconda3/envs/tf/lib/python3.6/site-packages/django/db/models/query.py", line 55, in __iter__
    results = compiler.execute_sql(chunked_fetch=self.chunked_fetch, chunk_size=self.chunk_size)
  File "/Users/anandaryanizar/anaconda3/envs/tf/lib/python3.6/site-packages/django/db/models/sql/compiler.py", line 1100, in execute_sql
    cursor.execute(sql, params)
  File "/Users/anandaryanizar/anaconda3/envs/tf/lib/python3.6/site-packages/django/db/backends/utils.py", line 99, in execute
    return super().execute(sql, params)
  File "/Users/anandaryanizar/anaconda3/envs/tf/lib/python3.6/site-packages/django/db/backends/utils.py", line 67, in execute
    return self._execute_with_wrappers(sql, params, many=False, executor=self._execute)
  File "/Users/anandaryanizar/anaconda3/envs/tf/lib/python3.6/site-packages/django/db/backends/utils.py", line 76, in _execute_with_wrappers
    return executor(sql, params, many, context)
  File "/Users/anandaryanizar/anaconda3/envs/tf/lib/python3.6/site-packages/django/db/backends/utils.py", line 84, in _execute
    return self.cursor.execute(sql, params)
  File "/Users/anandaryanizar/anaconda3/envs/tf/lib/python3.6/site-packages/django/db/utils.py", line 89, in __exit__
    raise dj_exc_value.with_traceback(traceback) from exc_value
  File "/Users/anandaryanizar/anaconda3/envs/tf/lib/python3.6/site-packages/django/db/backends/utils.py", line 84, in _execute
    return self.cursor.execute(sql, params)
  File "/Users/anandaryanizar/anaconda3/envs/tf/lib/python3.6/site-packages/django/db/backends/sqlite3/base.py", line 383, in execute
    return Database.Cursor.execute(self, query, params)
django.db.utils.OperationalError: no such column: classifier_classifier.model
WARNING:django.request:Not Found: /api/v1/predict/1/
INFO:django.utils.autoreload:/Users/anandaryanizar/Documents/Projects/Deep Learning/FakeNewsClassifier/classifier/classifier_api.py changed, reloading.
INFO:django.utils.autoreload:/Users/anandaryanizar/Documents/Projects/Deep Learning/FakeNewsClassifier/classifier/classifier_api.py changed, reloading.
